Workbook

Sheet Planning Roma
A1: PLATFORM | D1: RM
A3: DATE
A5: WEEK NR. | E5: C1 | F5: TEXTILE/OTHERS | L5: SHOES (TEMPE) | P5: ECOM | T5: TOTAL | V5: INTERSHOPS | X5: INTERSHOPS | Z5: INTERSHOPS | AB5: TEXTILE | AC5: TIPOLOGIA MEZZO | AD5: CODICE VETTORE | AE5: TARGA | AF5: AUTISTA
A6: ROUTE ID | B6: STORE CODE | C6: BRAND | D6: STORE | E6: DELIVERY DAY | F6: PLANNED CRTS TEXTILE | G6: RECEIVED CRTS TEXTILE | H6: PLANNED CRTS OTHERS | I6: RECEIVED CRTS OTHERS | J6: VOLUME | K6: WEIGHT | L6: PLANNED CRTS | M6: RECEIVED CRTS | N6: VOLUME | O6: WEIGHT | P6: PLANNED CRTS | Q6: RECEIVED CRTS | R6: VOLUME | S6: WEIGHT | T6: TOTAL VOLUME | U6: TOTAL WEIGHT | V6: ID STORE SENDER | W6: TOTAL CRTS | X6: ID STORE SENDER | Y6: TOTAL CRTS | Z6: ID STORE SENDER | AA6: TOTAL CRTS | AB6: TOTAL UNITS
A7: 1 | B7: 8601 | C7: BERSHKA | D7: TER-GRAN SASSO | E7: GIOVEDI' | F7: 49 | G7: 50 | H7: 8 | I7: 8 | J7: 5.22 | K7: 908 | L7: 6 | M7: 6 | N7: 0.65 | O7: 83 | P7: 3 | Q7: 3 | R7: 0.33 | S7: 18 | T7: =+J7+N7+R7 -> 6.2 | U7: =+K7+O7+S7 -> 1009 | AD7: 1805282
A8: 1 | B8: 8364 | C8: BERSHKA | D8: ROM-ROMA EST | E8: GIOVEDI' | F8: 94 | G8: 94 | H8: 6 | I8: 6 | J8: 9.44 | K8: 1652 | L8: 10 | M8: 10 | N8: 1.08 | O8: 149 | P8: 0 | Q8: 0 | R8: 0 | S8: 0 | T8: =+J8+N8+R8 -> 10.52 | U8: =+K8+O8+S8 -> 1801 | AD8: 1805282
A9: 1 | B9: 14825 | C9: BERSHKA | D9: ROM-P.DI ROMA | E9: GIOVEDI' | F9: 172 | G9: 170 | H9: 24 | I9: 10 | J9: 17.69 | K9: 3091 | L9: 14 | M9: 14 | N9: 1.38 | O9: 179 | P9: 0 | Q9: 0 | R9: 0 | S9: 0 | T9: =+J9+N9+R9 -> 19.07 | U9: =+K9+O9+S9 -> 3270 | AD9: 1805282
A10: 1 | B10: 12899 | C10: BERSHKA | D10: ROM-GRAN ROMA | E10: MERCOLEDI' | F10: 46 | G10: 47 | H10: 3 | I10: 3 | J10: 4.3 | K10: 717 | L10: 7 | M10: 7 | N10: 0.68 | O10: 85 | P10: 0 | Q10: 0 | R10: 0 | S10: 0 | T10: =+J10+N10+R10 -> 4.98 | U10: =+K10+O10+S10 -> 802 | AD10: 1805282
A11: 1 | B11: 8428 | C11: BERSHKA | D11: ROM-EUROMA2 | E11: GIOVEDI' | F11: 127 | G11: 130 | H11: 9 | I11: 2 | J11: 12.04 | K11: 2109 | L11: 14 | M11: 14 | N11: 1.51 | O11: 197 | P11: 0 | Q11: 0 | R11: 0 | S11: 0 | T11: =+J11+N11+R11 -> 13.55 | U11: =+K11+O11+S11 -> 2306 | AD11: 1805282
A12: 1 | B12: 8453 | C12: BERSHKA | D12: PER-COLLESTRADA | E12: GIOVEDI' | F12: 58 | G12: 58 | H12: 8 | I12: 8 | J12: 6.02 | K12: 970 | L12: 6 | M12: 6 | N12: 0.57 | O12: 67 | P12: 3 | Q12: 3 | R12: 0.3 | S12: 17 | T12: =+J12+N12+R12 -> 6.89 | U12: =+K12+O12+S12 -> 1054 | AD12: 1805282
A13: 1 | B13: 16037 | C13: BERSHKA | D13: LATI-LATINAFIOR | E13: MERCOLEDI' | F13: 67 | G13: 70 | H13: 4 | I13: 0 | J13: 6.97 | K13: 1197 | L13: 6 | M13: 6 | N13: 0.65 | O13: 77 | P13: 3 | Q13: 3 | R13: 0.33 | S13: 16 | T13: =+J13+N13+R13 -> 7.95 | U13: =+K13+O13+S13 -> 1290 | AD13: 1805282
A14: 1 | B14: 11796 | C14: BERSHKA | D14: CITT-PESCARA NO | E14: MERCOLEDI' | F14: 30 | G14: 29 | H14: 0 | I14: 0 | J14: 2.94 | K14: 480 | L14: 4 | M14: 4 | N14: 0.43 | O14: 55 | P14: 2 | Q14: 2 | R14: 0.22 | S14: 13 | T14: =+J14+N14+R14 -> 3.59 | U14: =+K14+O14+S14 -> 548 | AD14: 1805282
A15: 1 | B15: 16351 | C15: BERSHKA | D15: CHIETI-MEGALO | E15: MERCOLEDI' | F15: 91 | G15: 94 | H15: 10 | I15: 7 | J15: 9.48 | K15: 1690 | L15: 12 | M15: 12 | N15: 1.3 | O15: 162 | P15: 2 | Q15: 2 | R15: 0.22 | S15: 9 | T15: =+J15+N15+R15 -> 11 | U15: =+K15+O15+S15 -> 1861 | AD15: 1805282
A16: 1 | B16: 14010 | C16: BERSHKA | D16: ROM-OTTAVIANO | E16: GIOVEDI' | F16: 141 | G16: 139 | H16: 9 | I16: 10 | J16: 13.77 | K16: 2385 | L16: 12 | M16: 12 | N16: 1.16 | O16: 152 | P16: 0 | Q16: 0 | R16: 0 | S16: 0 | T16: =+J16+N16+R16 -> 14.93 | U16: =+K16+O16+S16 -> 2537 | AD16: 1805282
A17: 1 | B17: 4518 | C17: MASSIMO DUTTI | D17: ROM-EUROMA2 | E17: GIOVEDI' | F17: 45 | G17: 35 | H17: 5 | I17: 14 | J17: 4.96 | K17: 710 | L17: 4 | M17: 3 | N17: 0.43 | O17: 45 | P17: 0 | Q17: 0 | R17: 0 | S17: 0 | T17: =+J17+N17+R17 -> 5.39 | U17: =+K17+O17+S17 -> 755 | AD17: 1805282
A18: 1 | B18: 2435 | C18: OYSHO | D18: ROM-P.DI ROMA | E18: GIOVEDI' | F18: 20 | G18: 20 | H18: 0 | I18: 0 | J18: 1.15 | K18: 186 | L18: 0 | M18: 0 | N18: 0 | O18: 0 | P18: 1 | Q18: 1 | R18: 0.1 | S18: 3 | T18: =+J18+N18+R18 -> 1.25 | U18: =+K18+O18+S18 -> 189 | AD18: 1805282
... A26: 1 | B26: 5349 | C26: PULL&BEAR | D26: ROM-EUROMA2 APT0 | E26: GIOVEDI' | F26: 167 | G26: 140 | H26: 0 | I26: 5 | J26: 14.83 | K26: 2407 | L26: 8 | M26: 8 | N26: 0.73 | O26: 71 | P26: 0 | Q26: 0 | R26: 0 | S26: 0 | T26: =+J26+N26+R26 -> 15.56 | U26: =+K26+O26+S26 -> 2478 | AD26: 1805282
A27: 1 | B27: 5349B | C27: PULL&BEAR | D27: ROM-EUROMA2 APT9 | E27: GIOVEDI' | F27: 0 | G27: 0 | H27: 0 | I27: 0 | J27: 0 | K27: 0 | L27: 0 | M27: 0 | N27: 0 | O27: 0 | P27: 0 | Q27: 0 | R27: 0 | S27: 0 | AD27: 1805282
A28: 1 | B28: 6525 | C28: PULL&BEAR | D28: PER-COLLESTRADA APT0 | E28: GIOVEDI' | F28: 120 | G28: 100 | H28: 2 | I28: 0 | J28: 11.39 | K28: 1733 | L28: 9 | M28: 10 | N28: 0.81 | O28: 90 | P28: 2 | Q28: 2 | R28: 0.18 | S28: 8 | T28: =+J28+N28+R28 -> 12.38 | U28: =+K28+O28+S28 -> 1831 | AD28: 1805282
A29: 1 | B29: 6525B | C29: PULL&BEAR | D29: PER-COLLESTRADA APT9 | E29: GIOVEDI' | F29: 0 | G29: 0 | H29: 0 | I29: 0 | J29: 0 | K29: 0 | L29: 0 | M29: 0 | N29: 0 | O29: 0 | P29: 0 | Q29: 0 | R29: 0 | S29: 0 | AD29: 1805282
A30: 1 | B30: 16564 | C30: PULL&BEAR | D30: CHIETI-MEGALO | E30: MERCOLEDI' | F30: 107 | G30: 96 | H30: 0 | I30: 0 | J30: 9.87 | K30: 1605 | L30: 5 | M30: 5 | N30: 0.54 | O30: 59 | P30: 0 | Q30: 0 | R30: 0 | S30: 0 | T30: =+J30+N30+R30 -> 10.41 | U30: =+K30+O30+S30 -> 1664 | AD30: 1805282
A31: 1 | B31: 11629 | C31: PULL&BEAR | D31: ASC-AL BATTENT | E31: GIOVEDI' | F31: 45 | G31: 38 | H31: 0 | I31: 0 | J31: 4 | K31: 630 | L31: 5 | M31: 5 | N31: 0.41 | O31: 40 | P31: 2 | Q31: 2 | R31: 0.18 | S31: 6 | T31: =+J31+N31+R31 -> 4.59 | U31: =+K31+O31+S31 -> 676 | AD31: 1805282
A32: 1 | B32: 7593 | C32: STRADIVARIUS | D32: ROM-VIA TUSCOLA | E32: MERCOLEDI' | F32: 62 | G32: 63 | H32: 0 | I32: 0 | J32: 6.58 | K32: 1038 | L32: 11 | M32: 11 | N32: 1.19 | O32: 129 | P32: 0 | Q32: 0 | R32: 0 | S32: 0 | T32: =+J32+N32+R32 -> 7.77 | U32: =+K32+O32+S32 -> 1167 | AD32: 1805282
A33: 1 | B33: 2898 | C33: STRADIVARIUS | D33: ROM-ROMA EST | E33: GIOVEDI' | F33: 88 | G33: 90 | H33: 0 | I33: 0 | J33: 9.27 | K33: 1495 | L33: 9 | M33: 9 | N33: 0.89 | O33: 93 | P33: 0 | Q33: 0 | R33: 0 | S33: 0 | T33: =+J33+N33+R33 -> 10.16 | U33: =+K33+O33+S33 -> 1588 | AD33: 1805282
A34: 1 | B34: 12093 | C34: STRADIVARIUS | D34: ROM-GRAN ROMA | E34: MERCOLEDI' | F34: 39 | G34: 46 | H34: 0 | I34: 0 | J34: 4.22 | K34: 660 | L34: 9 | M34: 9 | N34: 0.97 | O34: 106 | P34: 0 | Q34: 0 | R34: 0 | S34: 0 | T34: =+J34+N34+R34 -> 5.19 | U34: =+K34+O34+S34 -> 766 | AD34: 1805282
A35: 1 | B35: 2917 | C35: STRADIVARIUS | D35: ROM-EUROMA2 | E35: MERCOLEDI' | F35: 96 | G35: 95 | H35: 0 | I35: 1 | J35: 10.01 | K35: 1608 | L35: 15 | M35: 15 | N35: 1.51 | O35: 164 | P35: 0 | Q35: 0 | R35: 0 | S35: 0 | T35: =+J35+N35+R35 -> 11.52 | U35: =+K35+O35+S35 -> 1772 | AD35: 1805282
A36: 1 | B36: 10265 | C36: STRADIVARIUS | D36: PES-VITTORIO E | E36: MERCOLEDI' | F36: 35 | G36: 38 | H36: 2 | I36: 1 | J36: 3.82 | K36: 535 | L36: 8 | M36: 8 | N36: 0.81 | O36: 84 | P36: 0 | Q36: 0 | R36: 0 | S36: 0 | T36: =+J36+N36+R36 -> 4.63 | U36: =+K36+O36+S36 -> 619 | AD36: 1805282
A37: 1 | B37: 16647 | C37: STRADIVARIUS | D37: CHIETI-MEGALO | E37: MERCOLEDI' | F37: 61 | G37: 59 | H37: 0 | I37: 2 | J37: 6.4 | K37: 958 | L37: 9 | M37: 9 | N37: 0.97 | O37: 108 | P37: 0 | Q37: 0 | R37: 0 | S37: 0 | T37: =+J37+N37+R37 -> 7.37 | U37: =+K37+O37+S37 -> 1066 | AD37: 1805282
A38: 1 | B38: 12154 | C38: STRADIVARIUS | D38: ASC-AL BATTENT | E38: GIOVEDI' | F38: 40 | G38: 50 | H38: 5 | I38: 0 | J38: 4.97 | K38: 743 | L38: 12 | M38: 12 | N38: 1.13 | O38: 128 | P38: 0 | Q38: 0 | R38: 0 | S38: 0 | T38: =+J38+N38+R38 -> 6.1 | U38: =+K38+O38+S38 -> 871 | AD38: 1805282
A39: 1 | B39: 12271 | C39: ZARA | D39: TER-GRAN SASSO | E39: GIOVEDI' | F39: 178 | G39: 183 | H39: 7 | I39: 0 | J39: 22.18 | K39: 3134 | P39: 0 | Q39: 0 | R39: 0 | S39: 0 | T39: =+J39+N39+R39 -> 22.18 | U39: =+K39+O39+S39 -> 3134 | AD39: 1805282
A40: 1 | B40: 12271 | C40: ZARA SHOES | D40: TER-GRAN SASSO | E40: GIOVEDI' | L40: 10 | M40: 10 | N40: 1.08 | O40: 109 | T40: =+J40+N40+R40 -> 1.08 | U40: =+K40+O40+S40 -> 109 | AD40: 1805282
A41: 1 | B41: 1265 | C41: ZARA | D41: ROM-VIA APPIA | E41: MERCOLEDI' | F41: 254 | G41: 262 | H41: 7 | I41: 15 | J41: 30.88 | K41: 4637 | P41: 0 | Q41: 0 | R41: 0 | S41: 0 | T41: =+J41+N41+R41 -> 30.88 | U41: =+K41+O41+S41 -> 4637 | V41: 1C da | AD41: 1805282
A42: 1 | B42: 1265 | C42: ZARA SHOES | D42: ROM-VIA APPIA | E42: MERCOLEDI' | L42: 22 | M42: 22 | N42: 2.12 | O42: 236 | T42: =+J42+N42+R42 -> 2.12 | U42: =+K42+O42+S42 -> 236 | V42: 1C da | AD42: 1805282
A43: 1 | B43: 3534 | C43: ZARA | D43: ROM-ROMA EST | E43: MERCOLEDI' | F43: 289 | G43: 294 | H43: 8 | I43: 0 | J43: 36.48 | K43: 5315 | P43: 0 | Q43: 0 | R43: 0 | S43: 0 | T43: =+J43+N43+R43 -> 36.48 | U43: =+K43+O43+S43 -> 5315 | AD43: 1805282
A44: 1 | B44: 3534 | C44: ZARA SHOES | D44: ROM-ROMA EST | E44: MERCOLEDI' | L44: 17 | M44: 17 | N44: 1.78 | O44: 205 | T44: =+J44+N44+R44 -> 1.78 | U44: =+K44+O44+S44 -> 205 | AD44: 1805282
A45: 1 | B45: 3680 | C45: ZARA | D45: ROM-P.DI ROMA APT 0 | E45: MERCOLEDI' | F45: 230 | G45: 19 | H45: 31 | I45: 2 | J45: 29.26 | K45: 4144 | P45: 0 | Q45: 0 | R45: 0 | S45: 0 | T45: =+J45+N45+R45 -> 29.26 | U45: =+K45+O45+S45 -> 4144 | V45: 17C da 215C da 2C da | AD45: 1805282
A46: 1 | B46: 3680 | C46: ZARA SHOES | D46: ROM-P.DI ROMA | E46: MERCOLEDI' | L46: 33 | M46: 33 | N46: 3.11 | O46: 357 | T46: =+J46+N46+R46 -> 3.11 | U46: =+K46+O46+S46 -> 357 | V46: 17C da 215C da 2C da | AD46: 1805282
A47: 1 | B47: 3680 | C47: ZARA | D47: ROM-P.DI ROMA APT0 | E47: MERCOLEDI' | J47: 0 | K47: 0 | V47: 17C da 215C da 2C da | AD47: 1805282
A48: 1 | B48: 3680B | C48: ZARA | D48: ROM-P.DI ROMA APT9 | E48: GIOVEDI' | F48: 0 | G48: 0 | H48: 0 | I48: 0 | J48: 0 | K48: 0 | L48: 0 | M48: 0 | N48: 0 | O48: 0 | P48: 0 | Q48: 0 | R48: 0 | S48: 0 | AD48: 1805282
A49: 1 | B49: 9226 | C49: ZARA | D49: ROM-P BOCCONI | E49: MERCOLEDI' | F49: 273 | G49: 0 | H49: 16 | I49: 0 | J49: 32.86 | K49: 4313 | P49: 0 | Q49: 0 | R49: 0 | S49: 0 | T49: =+J49+N49+R49 -> 32.86 | U49: =+K49+O49+S49 -> 4313 | AD49: 1805282
...

Sheet DATA ENTRY
A1: HUB | B1: ROUTE DATE | C1: ROUTE NR | D1: STOP NR | E1: SERVICE TYPE | F1: BRAND CODE/NAME | G1: SHOP CODE | H1: TEX VOLUME MC | I1: TEX GROSS WEIGHT KG | J1: TEX CRTS | K1: OTHER VOLUME MC | L1: OTHER GROSS WEIGHT KG | M1: OTHER CRTS | N1: SHOE VOLUME | O1: SHOE GROSS WEIGHT KG | P1: SHOE CRTS | Q1: ECO VOLUME MC | R1: ECO GROSS WEIGHT KG | S1: ECO CRTS | T1: INTERSHOP CODE 1 | U1: INTERSHOP CRT 1 | V1: INTERSHOP CODE 2 | W1: INTERSHOP CRT 2 | X1: INTERSHOP CODE 3 | Y1: INTERSHOP CRT 3 | Z1: PIECES HAN | AA1: HAULIER | AB1: REG. VEHICLE | AC1: DRIVER | AD1: MATE | AE1: START TIME | AF1: NOTE LINE 1
A2: ='Planning Roma'!$D$1 -> RM | B2: ='Planning Roma'!$D$3 | C2: ='Planning Roma'!$A$7 -> 1 | E2: CS | F2: ='Planning Roma'!C7 -> BERSHKA | G2: ='Planning Roma'!B7 -> 8601 | H2: ='Planning Roma'!J7 -> 5.22 | I2: ='Planning Roma'!K7 -> 908 | J2: ='Planning Roma'!G7 -> 50 | M2: ='Planning Roma'!I7 -> 8 | N2: ='Planning Roma'!N7 -> 0.65 | O2: ='Planning Roma'!O7 -> 83 | P2: ='Planning Roma'!M7 -> 6 | Q2: ='Planning Roma'!R7 -> 0.33 | R2: ='Planning Roma'!S7 -> 18 | S2: ='Planning Roma'!Q7 -> 3 | T2: ='Planning Roma'!V7 | U2: ='Planning Roma'!W7 -> 0 | V2: ='Planning Roma'!X7 -> 0 | W2: ='Planning Roma'!Y7 -> 0 | X2: ='Planning Roma'!Z7 -> 0 | Y2: ='Planning Roma'!AA7 -> 0 | Z2: ='Planning Roma'!AB7 -> 0 | AA2: 1805282 | AB2: ='Planning Roma'!AE7 -> 0 | AC2: ='Planning Roma'!AF7 -> 0 | AI2: =SUM(H2:Z2) -> 1082.2
A3: ='Planning Roma'!$D$1 -> RM | B3: ='Planning Roma'!$D$3 | C3: ='Planning Roma'!$A$7 -> 1 | E3: CS | F3: ='Planning Roma'!C8 -> BERSHKA | G3: ='Planning Roma'!B8 -> 8364 | H3: ='Planning Roma'!J8 -> 9.44 | I3: ='Planning Roma'!K8 -> 1652 | J3: ='Planning Roma'!G8 -> 94 | M3: ='Planning Roma'!I8 -> 6 | N3: ='Planning Roma'!N8 -> 1.08 | O3: ='Planning Roma'!O8 -> 149 | P3: ='Planning Roma'!M8 -> 10 | Q3: ='Planning Roma'!R8 -> 0 | R3: ='Planning Roma'!S8 -> 0 | S3: ='Planning Roma'!Q8 -> 0 | T3: ='Planning Roma'!V8 | U3: ='Planning Roma'!W8 -> 0 | V3: ='Planning Roma'!X8 -> 0 | W3: ='Planning Roma'!Y8 -> 0 | X3: ='Planning Roma'!Z8 -> 0 | Y3: ='Planning Roma'!AA8 -> 0 | Z3: ='Planning Roma'!AB8 -> 0 | AA3: 1805282 | AB3: ='Planning Roma'!AE8 -> 0 | AC3: ='Planning Roma'!AF8 -> 0 | AI3: =SUM(H3:Z3) -> 1921.52
A4: ='Planning Roma'!$D$1 -> RM | B4: ='Planning Roma'!$D$3 | C4: ='Planning Roma'!$A$7 -> 1 | E4: CS | F4: ='Planning Roma'!C9 -> BERSHKA | G4: ='Planning Roma'!B9 -> 14825 | H4: ='Planning Roma'!J9 -> 17.69 | I4: ='Planning Roma'!K9 -> 3091 | J4: ='Planning Roma'!G9 -> 170 | M4: ='Planning Roma'!I9 -> 10 | N4: ='Planning Roma'!N9 -> 1.38 | O4: ='Planning Roma'!O9 -> 179 | P4: ='Planning Roma'!M9 -> 14 | Q4: ='Planning Roma'!R9 -> 0 | R4: ='Planning Roma'!S9 -> 0 | S4: ='Planning Roma'!Q9 -> 0 | T4: ='Planning Roma'!V9 | U4: ='Planning Roma'!W9 -> 0 | V4: ='Planning Roma'!X9 -> 0 | W4: ='Planning Roma'!Y9 -> 0 | X4: ='Planning Roma'!Z9 -> 0 | Y4: ='Planning Roma'!AA9 -> 0 | Z4: ='Planning Roma'!AB9 -> 0 | AA4: 1805282 | AB4: ='Planning Roma'!AE9 -> 0 | AC4: ='Planning Roma'!AF9 -> 0 | AI4: =SUM(H4:Z4) -> 3483.07
A5: ='Planning Roma'!$D$1 -> RM | B5: ='Planning Roma'!$D$3 | C5: ='Planning Roma'!$A$7 -> 1 | E5: CS | F5: ='Planning Roma'!C10 -> BERSHKA | G5: ='Planning Roma'!B10 -> 12899 | H5: ='Planning Roma'!J10 -> 4.3 | I5: ='Planning Roma'!K10 -> 717 | J5: ='Planning Roma'!G10 -> 47 | M5: ='Planning Roma'!I10 -> 3 | N5: ='Planning Roma'!N10 -> 0.68 | O5: ='Planning Roma'!O10 -> 85 | P5: ='Planning Roma'!M10 -> 7 | Q5: ='Planning Roma'!R10 -> 0 | R5: ='Planning Roma'!S10 -> 0 | S5: ='Planning Roma'!Q10 -> 0 | T5: ='Planning Roma'!V10 | U5: ='Planning Roma'!W10 -> 0 | V5: ='Planning Roma'!X10 -> 0 | W5: ='Planning Roma'!Y10 -> 0 | X5: ='Planning Roma'!Z10 -> 0 | Y5: ='Planning Roma'!AA10 -> 0 | Z5: ='Planning Roma'!AB10 -> 0 | AA5: 1805282 | AB5: ='Planning Roma'!AE10 -> 0 | AC5: ='Planning Roma'!AF10 -> 0 | AI5: =SUM(H5:Z5) -> 863.98
A6: ='Planning Roma'!$D$1 -> RM | B6: ='Planning Roma'!$D$3 | C6: ='Planning Roma'!$A$7 -> 1 | E6: CS | F6: ='Planning Roma'!C11 -> BERSHKA | G6: ='Planning Roma'!B11 -> 8428 | H6: ='Planning Roma'!J11 -> 12.04 | I6: ='Planning Roma'!K11 -> 2109 | J6: ='Planning Roma'!G11 -> 130 | M6: ='Planning Roma'!I11 -> 2 | N6: ='Planning Roma'!N11 -> 1.51 | O6: ='Planning Roma'!O11 -> 197 | P6: ='Planning Roma'!M11 -> 14 | Q6: ='Planning Roma'!R11 -> 0 | R6: ='Planning Roma'!S11 -> 0 | S6: ='Planning Roma'!Q11 -> 0 | T6: ='Planning Roma'!V11 | U6: ='Planning Roma'!W11 -> 0 | V6: ='Planning Roma'!X11 -> 0 | W6: ='Planning Roma'!Y11 -> 0 | X6: ='Planning Roma'!Z11 -> 0 | Y6: ='Planning Roma'!AA11 -> 0 | Z6: ='Planning Roma'!AB11 -> 0 | AA6: 1805282 | AB6: ='Planning Roma'!AE11 -> 0 | AC6: ='Planning Roma'!AF11 -> 0 | AI6: =SUM(H6:Z6) -> 2465.55
A7: ='Planning Roma'!$D$1 -> RM | B7: ='Planning Roma'!$D$3 | C7: ='Planning Roma'!$A$7 -> 1 | E7: CS | F7: ='Planning Roma'!C12 -> BERSHKA | G7: ='Planning Roma'!B12 -> 8453 | H7: ='Planning Roma'!J12 -> 6.02 | I7: ='Planning Roma'!K12 -> 970 | J7: ='Planning Roma'!G12 -> 58 | M7: ='Planning Roma'!I12 -> 8 | N7: ='Planning Roma'!N12 -> 0.57 | O7: ='Planning Roma'!O12 -> 67 | P7: ='Planning Roma'!M12 -> 6 | Q7: ='Planning Roma'!R12 -> 0.3 | R7: ='Planning Roma'!S12 -> 17 | S7: ='Planning Roma'!Q12 -> 3 | T7: ='Planning Roma'!V12 | U7: ='Planning Roma'!W12 -> 0 | V7: ='Planning Roma'!X12 -> 0 | W7: ='Planning Roma'!Y12 -> 0 | X7: ='Planning Roma'!Z12 -> 0 | Y7: ='Planning Roma'!AA12 -> 0 | Z7: ='Planning Roma'!AB12 -> 0 | AA7: 1805282 | AB7: ='Planning Roma'!AE12 -> 0 | AC7: ='Planning Roma'!AF12 -> 0 | AI7: =SUM(H7:Z7) -> 1135.89
A8: ='Planning Roma'!$D$1 -> RM | B8: ='Planning Roma'!$D$3 | C8: ='Planning Roma'!$A$7 -> 1 | E8: CS | F8: ='Planning Roma'!C13 -> BERSHKA | G8: ='Planning Roma'!B13 -> 16037 | H8: ='Planning Roma'!J13 -> 6.97 | I8: ='Planning Roma'!K13 -> 1197 | J8: ='Planning Roma'!G13 -> 70 | M8: ='Planning Roma'!I13 -> 0 | N8: ='Planning Roma'!N13 -> 0.65 | O8: ='Planning Roma'!O13 -> 77 | P8: ='Planning Roma'!M13 -> 6 | Q8: ='Planning Roma'!R13 -> 0.33 | R8: ='Planning Roma'!S13 -> 16 | S8: ='Planning Roma'!Q13 -> 3 | T8: ='Planning Roma'!V13 | U8: ='Planning Roma'!W13 -> 0 | V8: ='Planning Roma'!X13 -> 0 | W8: ='Planning Roma'!Y13 -> 0 | X8: ='Planning Roma'!Z13 -> 0 | Y8: ='Planning Roma'!AA13 -> 0 | Z8: ='Planning Roma'!AB13 -> 0 | AA8: 1805282 | AB8: ='Planning Roma'!AE13 -> 0 | AC8: ='Planning Roma'!AF13 -> 0 | AI8: =SUM(H8:Z8) -> 1376.95
A9: ='Planning Roma'!$D$1 -> RM | B9: ='Planning Roma'!$D$3 | C9: ='Planning Roma'!$A$7 -> 1 | E9: CS | F9: ='Planning Roma'!C14 -> BERSHKA | G9: ='Planning Roma'!B14 -> 11796 | H9: ='Planning Roma'!J14 -> 2.94 | I9: ='Planning Roma'!K14 -> 480 | J9: ='Planning Roma'!G14 -> 29 | M9: ='Planning Roma'!I14 -> 0 | N9: ='Planning Roma'!N14 -> 0.43 | O9: ='Planning Roma'!O14 -> 55 | P9: ='Planning Roma'!M14 -> 4 | Q9: ='Planning Roma'!R14 -> 0.22 | R9: ='Planning Roma'!S14 -> 13 | S9: ='Planning Roma'!Q14 -> 2 | T9: ='Planning Roma'!V14 -> 0 | U9: ='Planning Roma'!W14 -> 0 | V9: ='Planning Roma'!X14 -> 0 | W9: ='Planning Roma'!Y14 -> 0 | X9: ='Planning Roma'!Z14 -> 0 | Y9: ='Planning Roma'!AA14 -> 0 | Z9: ='Planning Roma'!AB14 -> 0 | AA9: 1805282 | AB9: ='Planning Roma'!AE14 -> 0 | AC9: ='Planning Roma'!AF14 -> 0 | AI9: =SUM(H9:Z9) -> 586.59
A10: ='Planning Roma'!$D$1 -> RM | B10: ='Planning Roma'!$D$3 | C10: ='Planning Roma'!$A$7 -> 1 | E10: CS | F10: ='Planning Roma'!C15 -> BERSHKA | G10: ='Planning Roma'!B15 -> 16351 | H10: ='Planning Roma'!J15 -> 9.48 | I10: ='Planning Roma'!K15 -> 1690 | J10: ='Planning Roma'!G15 -> 94 | M10: ='Planning Roma'!I15 -> 7 | N10: ='Planning Roma'!N15 -> 1.3 | O10: ='Planning Roma'!O15 -> 162 | P10: ='Planning Roma'!M15 -> 12 | Q10: ='Planning Roma'!R15 -> 0.22 | R10: ='Planning Roma'!S15 -> 9 | S10: ='Planning Roma'!Q15 -> 2 | T10: ='Planning Roma'!V15 | U10: ='Planning Roma'!W15 -> 0 | V10: ='Planning Roma'!X15 -> 0 | W10: ='Planning Roma'!Y15 -> 0 | X10: ='Planning Roma'!Z15 -> 0 | Y10: ='Planning Roma'!AA15 -> 0 | Z10: ='Planning Roma'!AB15 -> 0 | AA10: 1805282 | AB10: ='Planning Roma'!AE15 -> 0 | AC10: ='Planning Roma'!AF15 -> 0 | AI10: =SUM(H10:Z10) -> 1987
A11: ='Planning Roma'!$D$1 -> RM | B11: ='Planning Roma'!$D$3 | C11: ='Planning Roma'!$A$7 -> 1 | E11: CS | F11: ='Planning Roma'!C16 -> BERSHKA | G11: ='Planning Roma'!B16 -> 14010 | H11: ='Planning Roma'!J16 -> 13.77 | I11: ='Planning Roma'!K16 -> 2385 | J11: ='Planning Roma'!G16 -> 139 | M11: ='Planning Roma'!I16 -> 10 | N11: ='Planning Roma'!N16 -> 1.16 | O11: ='Planning Roma'!O16 -> 152 | P11: ='Planning Roma'!M16 -> 12 | Q11: ='Planning Roma'!R16 -> 0 | R11: ='Planning Roma'!S16 -> 0 | S11: ='Planning Roma'!Q16 -> 0 | T11: ='Planning Roma'!V16 | U11: ='Planning Roma'!W16 -> 0 | V11: ='Planning Roma'!X16 -> 0 | W11: ='Planning Roma'!Y16 -> 0 | X11: ='Planning Roma'!Z16 -> 0 | Y11: ='Planning Roma'!AA16 -> 0 | Z11: ='Planning Roma'!AB16 -> 0 | AA11: 1805282 | AB11: ='Planning Roma'!AE16 -> 0 | AC11: ='Planning Roma'!AF16 -> 0 | AI11: =SUM(H11:Z11) -> 2712.93
A12: ='Planning Roma'!$D$1 -> RM | B12: ='Planning Roma'!$D$3 | C12: ='Planning Roma'!$A$7 -> 1 | E12: CS | F12: ='Planning Roma'!C17 -> MASSIMO DUTTI | G12: ='Planning Roma'!B17 -> 4518 | H12: ='Planning Roma'!J17 -> 4.96 | I12: ='Planning Roma'!K17 -> 710 | J12: ='Planning Roma'!G17 -> 35 | M12: ='Planning Roma'!I17 -> 14 | N12: ='Planning Roma'!N17 -> 0.43 | O12: ='Planning Roma'!O17 -> 45 | P12: ='Planning Roma'!M17 -> 3 | Q12: ='Planning Roma'!R17 -> 0 | R12: ='Planning Roma'!S17 -> 0 | S12: ='Planning Roma'!Q17 -> 0 | T12: ='Planning Roma'!V17 | U12: ='Planning Roma'!W17 -> 0 | V12: ='Planning Roma'!X17 -> 0 | W12: ='Planning Roma'!Y17 -> 0 | X12: ='Planning Roma'!Z17 -> 0 | Y12: ='Planning Roma'!AA17 -> 0 | Z12: ='Planning Roma'!AB17 -> 0 | AA12: 1805282 | AB12: ='Planning Roma'!AE17 -> 0 | AC12: ='Planning Roma'!AF17 -> 0 | AI12: =SUM(H12:Z12) -> 812.39
A13: ='Planning Roma'!$D$1 -> RM | B13: ='Planning Roma'!$D$3 | C13: ='Planning Roma'!$A$7 -> 1 | E13: CS | F13: ='Planning Roma'!C18 -> OYSHO | G13: ='Planning Roma'!B18 -> 2435 | H13: ='Planning Roma'!J18 -> 1.15 | I13: ='Planning Roma'!K18 -> 186 | J13: ='Planning Roma'!G18 -> 20 | M13: ='Planning Roma'!I18 -> 0 | N13: ='Planning Roma'!N18 -> 0 | O13: ='Planning Roma'!O18 -> 0 | P13: ='Planning Roma'!M18 -> 0 | Q13: ='Planning Roma'!R18 -> 0.1 | R13: ='Planning Roma'!S18 -> 3 | S13: ='Planning Roma'!Q18 -> 1 | T13: ='Planning Roma'!V18 | U13: ='Planning Roma'!W18 -> 0 | V13: ='Planning Roma'!X18 -> 0 | W13: ='Planning Roma'!Y18 -> 0 | X13: ='Planning Roma'!Z18 -> 0 | Y13: ='Planning Roma'!AA18 -> 0 | Z13: ='Planning Roma'!AB18 -> 0 | AA13: 1805282 | AB13: ='Planning Roma'!AE18 -> 0 | AC13: ='Planning Roma'!AF18 -> 0 | AI13: =SUM(H13:Z13) -> 211.25
... A55: ='Planning Roma'!$D$1 -> RM | B55: ='Planning Roma'!$D$3 | C55: ='Planning Roma'!$A$7 -> 1 | E55: CS | F55: ='Planning Roma'!C60 -> ZARA SHOES | G55: ='Planning Roma'!B60 -> 3503 | H55: ='Planning Roma'!J60 -> 0 | I55: ='Planning Roma'!K60 -> 0 | J55: ='Planning Roma'!G60 -> 0 | M55: ='Planning Roma'!I60 -> 0 | N55: ='Planning Roma'!N60 -> 2.27 | O55: ='Planning Roma'!O60 -> 275 | P55: ='Planning Roma'!M60 -> 25 | Q55: ='Planning Roma'!R60 -> 0 | R55: ='Planning Roma'!S60 -> 0 | S55: ='Planning Roma'!Q60 -> 0 | T55: ='Planning Roma'!V60 | U55: ='Planning Roma'!W60 -> 0 | V55: ='Planning Roma'!X60 -> 0 | W55: ='Planning Roma'!Y60 -> 0 | X55: ='Planning Roma'!Z60 -> 0 | Y55: ='Planning Roma'!AA60 -> 0 | Z55: ='Planning Roma'!AB60 -> 0 | AA55: 1805282 | AB55: ='Planning Roma'!AE60 -> 0 | AC55: ='Planning Roma'!AF60 -> 0 | AI55: =SUM(H55:Z55) -> 302.27
A56: ='Planning Roma'!$D$1 -> RM | B56: ='Planning Roma'!$D$3 | C56: ='Planning Roma'!$A$7 -> 1 | E56: CS | F56: ='Planning Roma'!C61 -> ZARA | G56: ='Planning Roma'!B61 -> 3503B | H56: ='Planning Roma'!J61 -> 0 | I56: ='Planning Roma'!K61 -> 0 | J56: ='Planning Roma'!G61 -> 0 | M56: ='Planning Roma'!I61 -> 0 | N56: ='Planning Roma'!N61 -> 0 | O56: ='Planning Roma'!O61 -> 0 | P56: ='Planning Roma'!M61 -> 0 | Q56: ='Planning Roma'!R61 -> 0 | R56: ='Planning Roma'!S61 -> 0 | S56: ='Planning Roma'!Q61 -> 0 | T56: ='Planning Roma'!V61 | U56: ='Planning Roma'!W61 -> 0 | V56: ='Planning Roma'!X61 -> 0 | W56: ='Planning Roma'!Y61 -> 0 | X56: ='Planning Roma'!Z61 -> 0 | Y56: ='Planning Roma'!AA61 -> 0 | Z56: ='Planning Roma'!AB61 -> 0 | AA56: 1805282 | AB56: ='Planning Roma'!AE61 -> 0 | AC56: ='Planning Roma'!AF61 -> 0 | AI56: =SUM(J56:Z56) -> 0
A57: ='Planning Roma'!$D$1 -> RM | B57: ='Planning Roma'!$D$3 | C57: ='Planning Roma'!$A$7 -> 1 | E57: CS | F57: ='Planning Roma'!C62 -> ZARA HOME | G57: ='Planning Roma'!B62 -> 1971 | K57: ='Planning Roma'!J62 -> 15.96 | L57: ='Planning Roma'!K62 -> 1606 | M57: ='Planning Roma'!I62 -> 0 | N57: ='Planning Roma'!N62 -> 0.32 | O57: ='Planning Roma'!O62 -> 38 | P57: ='Planning Roma'!M62 -> 3 | Q57: ='Planning Roma'!R62 -> 1.44 | R57: ='Planning Roma'!S62 -> 69 | S57: ='Planning Roma'!Q62 -> 15 | T57: ='Planning Roma'!V62 -> 3C da 169C da | U57: ='Planning Roma'!W62 -> 0 | V57: ='Planning Roma'!X62 -> 0 | W57: ='Planning Roma'!Y62 -> 0 | X57: ='Planning Roma'!Z62 -> 0 | Y57: ='Planning Roma'!AA62 -> 0 | Z57: ='Planning Roma'!AB62 -> 0 | AA57: 1805282 | AB57: ='Planning Roma'!AE62 -> 0 | AC57: ='Planning Roma'!AF62 -> 0 | AI57: =SUM(H57:Z57) -> 1748.72
A58: ='Planning Roma'!$D$1 -> RM | B58: ='Planning Roma'!$D$3 | C58: ='Planning Roma'!$A$7 -> 1 | E58: CS | F58: ='Planning Roma'!C63 -> ZARA HOME | G58: ='Planning Roma'!B63 -> 1755 | K58: ='Planning Roma'!J63 -> 8.83 | L58: ='Planning Roma'!K63 -> 942 | M58: ='Planning Roma'!I63 -> 114 | N58: ='Planning Roma'!N63 -> 0.14 | O58: ='Planning Roma'!O63 -> 13 | P58: ='Planning Roma'!M63 -> 2 | Q58: ='Planning Roma'!R63 -> 1.06 | R58: ='Planning Roma'!S63 -> 52 | S58: ='Planning Roma'!Q63 -> 11 | T58: ='Planning Roma'!V63 | U58: ='Planning Roma'!W63 -> 0 | V58: ='Planning Roma'!X63 -> 0 | W58: ='Planning Roma'!Y63 -> 0 | X58: ='Planning Roma'!Z63 -> 0 | Y58: ='Planning Roma'!AA63 -> 0 | Z58: ='Planning Roma'!AB63 -> 0 | AA58: 1805282 | AB58: ='Planning Roma'!AE63 -> 0 | AC58: ='Planning Roma'!AF63 -> 0 | AI58: =SUM(H58:Z58) -> 1144.03
A59: ='Planning Roma'!$D$1 -> RM | B59: ='Planning Roma'!$D$3 | C59: ='Planning Roma'!$A$7 -> 1 | E59: CS | F59: ='Planning Roma'!C64 -> ZARA HOME | G59: ='Planning Roma'!B64 -> 1984 | K59: ='Planning Roma'!J64 -> 21.81 | L59: ='Planning Roma'!K64 -> 2457 | M59: ='Planning Roma'!I64 -> 0 | N59: ='Planning Roma'!N64 -> 0.33 | O59: ='Planning Roma'!O64 -> 37 | P59: ='Planning Roma'!M64 -> 0 | Q59: ='Planning Roma'!R64 -> 0.86 | R59: ='Planning Roma'!S64 -> 51 | S59: ='Planning Roma'!Q64 -> 9 | T59: ='Planning Roma'!V64 -> 186C da 3C da 1C da | U59: ='Planning Roma'!W64 -> 0 | V59: ='Planning Roma'!X64 -> 0 | W59: ='Planning Roma'!Y64 -> 0 | X59: ='Planning Roma'!Z64 -> 0 | Y59: ='Planning Roma'!AA64 -> 0 | Z59: ='Planning Roma'!AB64 -> 0 | AA59: 1805282 | AB59: ='Planning Roma'!AE64 -> 0 | AC59: ='Planning Roma'!AF64 -> 0 | AI59: =SUM(H59:Z59) -> 2577
A60: ='Planning Roma'!$D$1 -> RM | B60: ='Planning Roma'!$D$3 | C60: ='Planning Roma'!$A$7 -> 1 | E60: CS | F60: ='Planning Roma'!C65 -> ZARA HOME APP | G60: ='Planning Roma'!B65 -> 1971 | H60: ='Planning Roma'!J65 -> 0 | I60: ='Planning Roma'!K65 -> 0 | J60: ='Planning Roma'!G65 -> 0 | M60: ='Planning Roma'!I65 -> 0 | N60: ='Planning Roma'!N65 -> 0 | O60: ='Planning Roma'!O65 -> 0 | P60: ='Planning Roma'!M65 -> 0 | Q60: ='Planning Roma'!R65 -> 0 | R60: ='Planning Roma'!S65 -> 0 | S60: ='Planning Roma'!Q65 -> 0 | T60: ='Planning Roma'!V65 -> 3C da 169C da | U60: ='Planning Roma'!W65 -> 0 | V60: ='Planning Roma'!X65 -> 0 | W60: ='Planning Roma'!Y65 -> 0 | X60: ='Planning Roma'!Z65 -> 0 | Y60: ='Planning Roma'!AA65 -> 0 | Z60: ='Planning Roma'!AB65 -> 0 | AA60: 1805282 | AB60: ='Planning Roma'!AE65 -> 0 | AC60: ='Planning Roma'!AF65 -> 0 | AI60: =SUM(H60:Z60) -> 0
A61: ='Planning Roma'!$D$1 -> RM | B61: ='Planning Roma'!$D$3 | C61: ='Planning Roma'!$A$7 -> 1 | E61: CS | F61: ='Planning Roma'!C66 -> ZARA HOME APP | G61: ='Planning Roma'!B66 -> 1984 | H61: ='Planning Roma'!J66 -> 0 | I61: ='Planning Roma'!K66 -> 0 | J61: ='Planning Roma'!G66 -> 0 | M61: ='Planning Roma'!I66 -> 0 | N61: ='Planning Roma'!N66 -> 0 | O61: ='Planning Roma'!O66 -> 0 | P61: ='Planning Roma'!M66 -> 0 | Q61: ='Planning Roma'!R66 -> 0 | R61: ='Planning Roma'!S66 -> 0 | S61: ='Planning Roma'!Q66 -> 0 | T61: ='Planning Roma'!V66 -> 186C da 3C da 1C da | U61: ='Planning Roma'!W66 -> 0 | V61: ='Planning Roma'!X66 -> 0 | W61: ='Planning Roma'!Y66 -> 0 | X61: ='Planning Roma'!Z66 -> 0 | Y61: ='Planning Roma'!AA66 -> 0 | Z61: ='Planning Roma'!AB66 -> 0 | AA61: 1805282 | AB61: ='Planning Roma'!AE66 -> 0 | AC61: ='Planning Roma'!AF66 -> 0 | AI61: =SUM(H61:Z61) -> 0
A62: ='Planning Roma'!$D$1 -> RM | B62: ='Planning Roma'!$D$3 | C62: ='Planning Roma'!$A$7 -> 1 | E62: CS | F62: ='Planning Roma'!C67 -> STRADIVARIUS | G62: ='Planning Roma'!B67 -> 6760 | H62: ='Planning Roma'!J67 -> 11.22 | I62: ='Planning Roma'!K67 -> 1661 | J62: ='Planning Roma'!G67 -> 106 | M62: ='Planning Roma'!I67 -> 0 | N62: ='Planning Roma'!N67 -> 0.93 | O62: ='Planning Roma'!O67 -> 102 | P62: ='Planning Roma'!M67 -> 10 | Q62: ='Planning Roma'!R67 -> 0 | R62: ='Planning Roma'!S67 -> 0 | S62: ='Planning Roma'!Q67 -> 0 | T62: ='Planning Roma'!V67 | U62: ='Planning Roma'!W67 -> 0 | V62: ='Planning Roma'!X67 -> 0 | W62: ='Planning Roma'!Y67 -> 0 | X62: ='Planning Roma'!Z67 -> 0 | Y62: ='Planning Roma'!AA67 -> 0 | Z62: ='Planning Roma'!AB67 -> 0 | AA62: 1805282 | AB62: ='Planning Roma'!AE67 -> 0 | AC62: ='Planning Roma'!AF67 -> 0 | AI62: =SUM(H62:Z62) -> 1891.15
A63: ='Planning Roma'!$D$1 -> RM | B63: ='Planning Roma'!$D$3 | C63: ='Planning Roma'!$A$7 -> 1 | E63: CS | F63: ='Planning Roma'!C68 -> ZARA | G63: ='Planning Roma'!B68 -> 15733 | H63: ='Planning Roma'!J68 -> 209.66 | I63: ='Planning Roma'!K68 -> 30097 | J63: ='Planning Roma'!G68 -> 854 | M63: ='Planning Roma'!I68 -> 0 | N63: ='Planning Roma'!N68 -> 0 | O63: ='Planning Roma'!O68 -> 0 | P63: ='Planning Roma'!M68 -> 0 | Q63: ='Planning Roma'!R68 -> 0 | R63: ='Planning Roma'!S68 -> 0 | S63: ='Planning Roma'!Q68 -> 0 | T63: ='Planning Roma'!V68 | U63: ='Planning Roma'!W68 -> 0 | V63: ='Planning Roma'!X68 -> 0 | W63: ='Planning Roma'!Y68 -> 0 | X63: ='Planning Roma'!Z68 -> 0 | Y63: ='Planning Roma'!AA68 -> 0 | Z63: ='Planning Roma'!AB68 -> 0 | AA63: 1805282 | AB63: ='Planning Roma'!AE68 -> 0 | AC63: ='Planning Roma'!AF68 -> 0 | AI63: =SUM(H63:Z63) -> 31160.66
A64: ='Planning Roma'!$D$1 -> RM | B64: ='Planning Roma'!$D$3 | C64: ='Planning Roma'!$A$7 -> 1 | E64: CS | F64: ='Planning Roma'!C69 -> ZARA SHOES | G64: ='Planning Roma'!B69 -> 15733 | H64: ='Planning Roma'!J69 -> 0 | I64: ='Planning Roma'!K69 -> 0 | J64: ='Planning Roma'!G69 -> 0 | M64: ='Planning Roma'!I69 -> 0 | N64: ='Planning Roma'!N69 -> 10.39 | O64: ='Planning Roma'!O69 -> 1176 | P64: ='Planning Roma'!M69 -> 56 | Q64: ='Planning Roma'!R69 -> 0 | R64: ='Planning Roma'!S69 -> 0 | S64: ='Planning Roma'!Q69 -> 0 | T64: ='Planning Roma'!V69 | U64: ='Planning Roma'!W69 -> 0 | V64: ='Planning Roma'!X69 -> 0 | W64: ='Planning Roma'!Y69 -> 0 | X64: ='Planning Roma'!Z69 -> 0 | Y64: ='Planning Roma'!AA69 -> 0 | Z64: ='Planning Roma'!AB69 -> 0 | AA64: 1805282 | AB64: ='Planning Roma'!AE69 -> 0 | AC64: ='Planning Roma'!AF69 -> 0 | AI64: =SUM(H64:Z64) -> 1242.39
A65: ='Planning Roma'!$D$1 -> RM | B65: ='Planning Roma'!$D$3 | C65: ='Planning Roma'!$A$7 -> 1 | E65: CS | F65: ='Planning Roma'!C70 -> BERSHKA | G65: ='Planning Roma'!B70 -> 5641 | H65: ='Planning Roma'!J70 -> 8.38 | I65: ='Planning Roma'!K70 -> 1427 | J65: ='Planning Roma'!G70 -> 85 | M65: ='Planning Roma'!I70 -> 0 | N65: ='Planning Roma'!N70 -> 0.68 | O65: ='Planning Roma'!O70 -> 92 | P65: ='Planning Roma'!M70 -> 7 | Q65: ='Planning Roma'!R70 -> 0.22 | R65: ='Planning Roma'!S70 -> 14 | S65: ='Planning Roma'!Q70 -> 2 | T65: ='Planning Roma'!V70 | U65: ='Planning Roma'!W70 -> 0 | V65: ='Planning Roma'!X70 -> 0 | W65: ='Planning Roma'!Y70 -> 0 | X65: ='Planning Roma'!Z70 -> 0 | Y65: ='Planning Roma'!AA70 -> 0 | Z65: ='Planning Roma'!AB70 -> 0 | AA65: 1805282 | AB65: ='Planning Roma'!AE70 -> 0 | AC65: ='Planning Roma'!AF70 -> 0 | AI65: =SUM(H65:Z65) -> 1636.28
A66: ='Planning Roma'!$D$1 -> RM | B66: ='Planning Roma'!$D$3 | C66: ='Planning Roma'!$A$7 -> 1 | E66: CS | F66: ='Planning Roma'!C71 -> PULL&BEAR | G66: ='Planning Roma'!B71 -> 5405 | H66: ='Planning Roma'!J71 -> 10.11 | I66: ='Planning Roma'!K71 -> 1584 | J66: ='Planning Roma'!G71 -> 92 | M66: ='Planning Roma'!I71 -> 0 | N66: ='Planning Roma'!N71 -> 0.49 | O66: ='Planning Roma'!O71 -> 53 | P66: ='Planning Roma'!M71 -> 7 | Q66: ='Planning Roma'!R71 -> 0.09 | R66: ='Planning Roma'!S71 -> 9 | S66: ='Planning Roma'!Q71 -> 1 | T66: ='Planning Roma'!V71 | U66: ='Planning Roma'!W71 -> 0 | V66: ='Planning Roma'!X71 -> 0 | W66: ='Planning Roma'!Y71 -> 0 | X66: ='Planning Roma'!Z71 -> 0 | Y66: ='Planning Roma'!AA71 -> 0 | Z66: ='Planning Roma'!AB71 -> 0 | AA66: 1805282 | AB66: ='Planning Roma'!AE71 -> 0 | AC66: ='Planning Roma'!AF71 -> 0 | AI66: =SUM(H66:Z66) -> 1756.69
A67: ='Planning Roma'!$D$1 -> RM | B67: ='Planning Roma'!$D$3 | C67: ='Planning Roma'!$A$7 -> 1 | E67: CS | F67: ='Planning Roma'!C72 -> STRADIVARIUS | G67: ='Planning Roma'!B72 -> 2972 | H67: ='Planning Roma'!J72 -> 6.54 | I67: ='Planning Roma'!K72 -> 916 | J67: ='Planning Roma'!G72 -> 60 | M67: ='Planning Roma'!I72 -> 0 | N67: ='Planning Roma'!N72 -> 0.96 | O67: ='Planning Roma'!O72 -> 106 | P67: ='Planning Roma'!M72 -> 10 | Q67: ='Planning Roma'!R72 -> 0 | R67: ='Planning Roma'!S72 -> 0 | S67: ='Planning Roma'!Q72 -> 0 | T67: ='Planning Roma'!V72 | U67: ='Planning Roma'!W72 -> 0 | V67: ='Planning Roma'!X72 -> 0 | W67: ='Planning Roma'!Y72 -> 0 | X67: ='Planning Roma'!Z72 -> 0 | Y67: ='Planning Roma'!AA72 -> 0 | Z67: ='Planning Roma'!AB72 -> 0 | AA67: 1805282 | AB67: ='Planning Roma'!AE72 -> 0 | AC67: ='Planning Roma'!AF72 -> 0 | AI67: =SUM(H67:Z67) -> 1099.5
A68: ='Planning Roma'!$D$1 -> RM | B68: ='Planning Roma'!$D$3 | C68: ='Planning Roma'!$A$7 -> 1 | E68: CS | F68: ='Planning Roma'!C73 -> MASSIMO DUTTI | G68: ='Planning Roma'!B73 -> 17019 | H68: ='Planning Roma'!J73 -> 7.05 | I68: ='Planning Roma'!K73 -> 881 | J68: ='Planning Roma'!G73 -> 44 | M68: ='Planning Roma'!I73 -> 32 | N68: ='Planning Roma'!N73 -> 1.22 | O68: ='Planning Roma'!O73 -> 123 | P68: ='Planning Roma'!M73 -> 25 | Q68: ='Planning Roma'!R73 -> 0 | R68: ='Planning Roma'!S73 -> 0 | S68: ='Planning Roma'!Q73 -> 0 | T68: ='Planning Roma'!V73 | U68: ='Planning Roma'!W73 -> 0 | V68: ='Planning Roma'!X73 -> 0 | W68: ='Planning Roma'!Y73 -> 0 | X68: ='Planning Roma'!Z73 -> 0 | Y68: ='Planning Roma'!AA73 -> 0 | Z68: ='Planning Roma'!AB73 -> 0 | AA68: 1805282 | AB68: ='Planning Roma'!AE73 -> 0 | AC68: ='Planning Roma'!AF73 -> 0 | AI68: =SUM(H68:Z68) -> 1113.27
